<html><head><meta charset="utf-8"></meta></head><body><h1 class="article-title" style="text-align:center;">Ruby异常</h1><div style="width:100%;float:left;" class="article-content">   
 <p>Ruby异常是一个对象，该类的异常或后代的实例。它代表一些特殊的条件。<br>在Ruby程序出现错误时，会引发异常行为。 默认情况下，Ruby程序在抛出异常时终止。</p> 
 <p>我们可以在Ruby中声明一些异常处理程序。 异常处理程序是一些代码块，当一些其他代码块发生异常时，该块被执行。</p> 
 <p>异常的情况以两种方式处理。 可以终止程序或处理异常。 如果要处理异常，可以提供一个<code>rescue</code>子句，这样程序控制就可以流向<code>rescue</code>子句。</p> 
 <p>当异常提出但未处理时，全局变量<code>$!</code>包含当前异常，<code>$@</code>包含当前异常的回溯。</p> 
 <p>Ruby预定义的类，如<code>Exception</code>及其子项可以用来处理程序的错误。 在Ruby异常层次结构中，大多数子类都扩展了<code>ClassError</code>类。 这些是正常的异常。</p> 
 <h2 id="h2-ruby-"><a name="Ruby类异常" class="reference-link"></a><span class="header-link octicon octicon-link"></span>Ruby类异常</h2>
 <p>异常的内置子类如下：</p> 
 <ul> 
  <li><em>NoMemoryError</em></li>
  <li><em>ScriptError</em></li>
  <li><em>SecurityError</em></li>
  <li><em>SignalException</em></li>
  <li><em>StandardError</em></li>
  <li><em>SystenExit</em></li>
  <li><em>SystemStackError</em></li>
  <li><em>fatal</em> - 不可以拯救</li>
 </ul> 
 <p><strong>示例</strong></p> 
 <pre><code class="lang-ruby">def raise_exception     
  puts 'I am before the raise.'     
  raise 'oops! An error has occured'     
  puts 'I am after the raise'     
end     
raise_exception
</code></pre> 
 <p>执行上面代码，输出结果如下 -</p> 
 <pre><code class="lang-shell">F:\worksp\ruby&gt;ruby exception-raise.rb
I am before the raise.
exception-raise.rb:6:in `raise_exception': oops! An error has occured (RuntimeError)
        from exception-raise.rb:9:in `&lt;main&gt;'

F:\worksp\ruby&gt;
</code></pre> 
 <p><code>raise</code>方法来自内核模块。</p> 
 <h2 id="h2-u5904u7406u5F02u5E38"><a name="处理异常" class="reference-link"></a><span class="header-link octicon octicon-link"></span>处理异常</h2>
 <p>为了处理异常，引发异常的代码包含在begin-end块中。 使用rescue子句，我们可以说明我们要处理的异常类型。</p> 
 <p>示例：</p> 
 <pre><code class="lang-ruby">#!/usr/bin/ruby   
#file: exception-raise_rescue.rb

def raise_and_rescue     
  begin     
    puts 'Before the raise.'     
    raise 'An error occured.'     
    puts 'After the raise.'     
  rescue     
    puts 'Code rescued.'     
  end     
  puts 'After the begin block.'     
end     
raise_and_rescue
</code></pre> 
 <p>执行上面代码，得到以下结果 - </p> 
 <pre><code class="lang-shell">F:\worksp\ruby&gt;ruby exception-raise_rescue.rb
Before the raise.
Code rescued.
After the begin block.

F:\worksp\ruby&gt;
</code></pre> 
 <p>在上面的例子中，中断的代码不能完全运行。 异常处理代码在开始结束块(<code>begin-end</code>)之后恢复。</p> 
 <p>如果在<code>rescue</code>子句中未定义任何参数，则该参数默认为<code>StandardError</code>。 每个<code>rescue</code>子句指定多个异常捕获。 如果<code>raise</code>没有使用任何参数，则可能会重新提出异常。</p> 
 <p><code>rescue</code>子句写在<code>begin/rescue</code>内，如果不是一个由<code>rescue</code>子句可处理的异常则将由下一个异常处理。</p> 
 <pre><code class="lang-ruby">begin  
code..  
rescue OneTypeOfException  
code..  
rescue AnotherTypeOfException  
 code..  
else  
  # Other exceptions  
end
</code></pre> 
 <p>在开始(<code>begin</code>)块中，每个具有引发异常的<code>rescue</code>子句将依次与每个参数进行比较。 当在<code>rescue</code>子句中指定的错误类型和异常名称相同或是该异常的超类时，则将匹配它。 如果没有异常，完成了<code>begin</code>语句的主体则执行<code>else</code>子句。 如果发生异常，则不会执行<code>else</code>子句。</p> 
 <h2 id="h2-exception-"><a name="Exception对象" class="reference-link"></a><span class="header-link octicon octicon-link"></span>Exception对象</h2>
 <p>异常对象是普通对象。<code>rescue</code>子句中的变量可以保存被拯救的异常。</p> 
 <p>示例:</p> 
 <pre><code class="lang-ruby">begin   
  raise 'an exception'   
rescue ZeroDivisionError =&gt; e   
  puts "Exception Class: #{ e.class.name }"   
  puts "Exception Message: #{ e.message }"   
  puts "Exception Backtrace: #{ e.backtrace }"   
end
</code></pre> 
 <p><code>Exception</code>类定义了两种方法用于返回有关异常的详细信息。 <code>message</code>方法返回一个定义错误说明的字符串。 <code>backtrace</code>方法返回一个字符串数组，表示在引发异常的时刻调用堆栈。</p> 
 <h2 id="h2--retry-"><a name="使用retry语句" class="reference-link"></a><span class="header-link octicon octicon-link"></span>使用retry语句</h2>
 <p>通常在<code>rescue</code>子句中，捕获异常并在<code>begin</code>块阻止继续执行代码。 使用<code>retry</code>语句，捕获块代码可以在捕获异常之后还可以从<code>begin</code>块处恢复。</p> 
 <p>语法：</p> 
 <pre><code class="lang-ruby">begin  
   code....  
rescue  
    # capture exceptions  
    retry  # program will run from the begin block  
end
</code></pre> 
 <p><strong>示例</strong></p> 
 <pre><code class="lang-ruby">#!/usr/bin/ruby   

begin   
   x = Dir.mkdir "alreadyExist"   
   if x   
      puts "Directory created"   
   end   
rescue   
   y = "newDir"   
   retry   
end
</code></pre> 
 <p>上述程序运行如下：</p> 
 <p><strong>步骤1</strong> - 在<code>begin</code>块中，编写代码以创建一个已经存在的目录。</p> 
 <p><strong>步骤2</strong> - 这将抛出一个错误。</p> 
 <p><strong>步骤3</strong> - 在<code>rescue</code>区，<code>y</code>被重新分配新值。</p> 
 <p><strong>步骤4</strong> - <code>retry</code>语句将转到<code>begin</code>块。</p> 
 <p><strong>步骤5</strong> - 将创建目录。</p> 
 <h2 id="h2--raise-"><a name="使用raise语句" class="reference-link"></a><span class="header-link octicon octicon-link"></span>使用raise语句</h2>
 <p><code>raise</code>语句用于引发异常。</p> 
 <p>语法：</p> 
 <pre><code class="lang-ruby">raise
</code></pre> 
 <p>或者 -</p> 
 <pre><code class="lang-ruby">raise "Error Message"
</code></pre> 
 <p>或者 -</p> 
 <pre><code class="lang-ruby">raise ExceptionType, "Error Message"
</code></pre> 
 <p>或者 -</p> 
 <pre><code class="lang-ruby">raise ExceptionType, "Error Message" condition
</code></pre> 
 <p>第一个语法，重新引发当前的异常。 它用于异常处理程序，其中异常在传递之前被拦截。</p> 
 <p>第二个语法，创建一个新的<code>RuntimeError</code>异常。 然后这个异常被引发为调用堆栈。</p> 
 <p>第三个语法，使用第一个参数创建一个异常，然后将关联消息设置为第二个参数。</p> 
 <p>第四个语法，类似第三个的语法。 在这里可以添加任何条件语句来引发异常。</p> 
 <p><strong>示例</strong></p> 
 <pre><code class="lang-ruby">#!/usr/bin/ruby   
# exceptions-raise-statement.rb

begin     
    puts 'code before raise.'     
    raise 'exception occurred.'     
    puts 'code after raise.'     
rescue     
    puts 'I am rescued.'     
end     
puts 'code after begin block.'
</code></pre> 
 <p>执行上面代码，得到以下结果 - </p>   
 <pre><code class="lang-shell">F:\worksp\ruby&gt;ruby exceptions-raise-statement.rb
code before raise.
I am rescued.
code after begin block.

F:\worksp\ruby&gt;
</code></pre> 
 <h2 id="h2--ensure-"><a name="使用ensure语句" class="reference-link"></a><span class="header-link octicon octicon-link"></span>使用ensure语句</h2>
 <p>有一个<code>ensure</code>子句，保证在代码结尾处的一些处理。无论是否引发异常 <code>ensure</code>块始终运行。 它放置在最后一个<code>rescue</code>子句之后，并且在块的结束时执行。</p> 
 <p>无论是否发生异常，异常被<code>rescue</code>或代码被未捕获的异常终止，<code>ensure</code>块都将运行。</p> 
 <p><strong>语法</strong></p> 
 <pre><code class="lang-ruby">begin   
  code..  
   #..raise exception  
rescue   
   #.. exception is rescued  
ensure   
   #.. This code will always execute.  
end
</code></pre> 
 <p><strong>示例代码</strong></p> 
 <pre><code class="lang-ruby">#!/usr/bin/ruby   
# file : exception-ensure-statment.rb
begin   
  raise 'Exception'   
rescue Exception =&gt; e   
  puts e.message   
  puts e.backtrace.inspect   
ensure   
  puts "The ensure code will always run"   
end
</code></pre> 
 <p>执行上面示例代码，得到以下结果 - </p> 
 <pre><code class="lang-shell">F:\worksp\ruby&gt;ruby exception-ensure-statment.rb
Exception
["exception-ensure-statment.rb:5:in `&lt;main&gt;'"]
The ensure code will always run

F:\worksp\ruby&gt;
</code></pre> 
 <h2 id="h2--else-"><a name="使用else语句" class="reference-link"></a><span class="header-link octicon octicon-link"></span>使用else语句</h2>
 <p><code>else</code>子句始终存在于<code>rescue</code>子句之后和<code>before</code>子句之前。 如果没有引发异常，则只执行其他块。</p> 
 <p>语法：</p> 
 <pre><code class="lang-ruby">begin   
   code..   
   #..raise exception  
rescue   
   # .. exception is rescued  
else  
   #.. executes if there is no exception  
ensure   
   #..  This code will always execute.  
end
</code></pre> 
 <p><strong>示例</strong></p> 
 <pre><code class="lang-ruby">#!/usr/bin/ruby   
# file : exception-else-statment.rb

begin   
 # raise 'A test exception.'   
 puts "no exception is raised"   
rescue Exception =&gt; e   
  puts e.message   
  puts e.backtrace.inspect   
else   
   puts "else code will be executed as no exception is raised."   
ensure   
  puts "ensure code will run"   
end
</code></pre> 
 <p>执行上面代码，得到以下结果 - </p> 
 <pre><code class="lang-shell">F:\worksp\ruby&gt;ruby exception-else-statment.rb
no exception is raised
else code will be executed as no exception is raised.
ensure code will run

F:\worksp\ruby&gt;
</code></pre> 
 <h2 id="h2-ruby-catch-throw-"><a name="Ruby catch和throw语句" class="reference-link"></a><span class="header-link octicon octicon-link"></span>Ruby catch和throw语句</h2>
 <p>Ruby <code>catch</code>和<code>throw</code>提供了一种在代码中不需要进一步工作的同时从执行中跳出来的方法。</p> 
 <p><code>catch</code>定义了一个标有给定名称的块。 它用于跳出嵌套代码。 使用<code>catch</code>语句，块将被正常执行，直到遇到<code>throw</code>。</p> 
 <p><code>catch</code>和<code>throw</code>方法比 <code>rescue</code> 和 <code>raise</code>快。 因此，更适合使用。</p> 
 <p>语法：</p> 
 <pre><code class="lang-ruby">throw :lablename  
#.. this  code will not be executed  
catch :lablename do  
#.. matching catch will be executed after a throw is encountered.  
end
</code></pre> 
 <p>或者 - </p> 
 <pre><code class="lang-ruby">throw :lablename condition  
#.. this code will not be executed  
catch :lablename do  
#.. matching catch will be executed after a throw is encountered.  
end
</code></pre> 
 <p><strong>示例</strong></p> 
 <pre><code class="lang-ruby">#!/usr/bin/ruby   
# file : exception-catch-throw.rb

def promptAndGet(prompt)   
   print prompt   
   res = readline.chomp   
   throw :quitRequested if res == "!"   
   return res   
end   

catch :quitRequested do   
   name = promptAndGet("Name: ")   
   age = promptAndGet("Occupation: ")   
   # ..   
   # process information   
end   
promptAndGet("Name:")
</code></pre> 
 <p>执行上面代码，得到以下结果 - </p> 
 <pre><code class="lang-shell">F:\worksp\ruby&gt;ruby exception-catch-throw.rb
Name: Maxsu
Occupation: Occupation
Name:Minsu

F:\worksp\ruby&gt;
</code></pre>
 <br>      
</div></body></html>